<?xml version="1.0"?>
<robot name="rissbot">

  <link name="link1">
    <visual>
      <geometry>
        <cylinder length="0.2" radius="0.02"/>
      </geometry>
    </visual>
  </link>

  <link name="link2">
    <visual>
      <origin xyz ="-0.1 0 0" />
      <geometry>
        <box size="0.2 0.02 0.02"/>
      </geometry>
    </visual>
  </link>

  <joint name="link1_to_link2" type="revolute">
    <origin xyz ="0 0 0.1" />
    <parent link="link1"/>
    <child link="link2"/>
    <axis xyz="0 0 1"/>
    <limit effort="30" velocity="1.0" lower="-2.2" upper="0.7" />
  </joint>

</robot>
